Workbook

Sheet Итого Месяцев
A1: СВОДКА ПО МЕСЯЦАМ — СУММЫ (сум)
A2: Категория | B2: 2025г.Ноябрь | C2: 2025г.Декабрь | D2: 2026г.Февраль | E2: 2026г.Март | F2: 2026г.Апрель | G2: 2026г.Май | H2: 2026г.Июнь | I2: 2026г.Июль | J2: Август | K2: Сентябрь | L2: Октябрь | M2: Ноябрь | N2: Декабрь
A3: Оплата рабочих | B3: =SUMIFS('Оплата рабочих'!$F$2:$F$106,'Оплата рабочих'!$A$2:$A$106,">=01.11.2025",'Оплата рабочих'!$A$2:$A$106,"<=30.11.2025") -> 91695000 | C3: =SUMIFS('Оплата рабочих'!$F$4:$F$106,'Оплата рабочих'!$A$4:$A$106,">=01.12.2025",'Оплата рабочих'!$A$4:$A$106,"<=31.12.2025") -> 0 | D3: =SUMIFS('Оплата рабочих'!$F$4:$F$106,'Оплата рабочих'!$A$4:$A$106,">=01.02.2026",'Оплата рабочих'!$A$4:$A$106,"<=28.02.2026") -> 407530000 | E3: =SUMIFS('Оплата рабочих'!$F$4:$F$106,'Оплата рабочих'!$A$4:$A$106,">=01.03.2026",'Оплата рабочих'!$A$4:$A$106,"<=31.03.2026") -> 459180000 | F3: =SUMIFS('Оплата рабочих'!$F$4:$F$106,'Оплата рабочих'!$A$4:$A$106,">=01.04.2026",'Оплата рабочих'!$A$4:$A$106,"<=30.04.2026") -> 0 | G3: =SUMIFS('Оплата рабочих'!$F$4:$F$106,'Оплата рабочих'!$A$4:$A$106,">=01.05.2026",'Оплата рабочих'!$A$4:$A$106,"<=31.05.2026") -> 703280000 | H3: =SUMIFS('Оплата рабочих'!$F$4:$F$106,'Оплата рабочих'!$A$4:$A$106,">=01.06.2026",'Оплата рабочих'!$A$4:$A$106,"<=30.06.2026") -> 937110000
A4: Строй Хоз.Товар | B4: =SUMIFS(Снабжения!$H$3:$H$1022,Снабжения!$A$3:$A$1022,">=01.11.2025",Снабжения!$A$3:$A$1022,"<=30.11.2025") -> 34494036 | C4: =SUMIFS(Снабжения!$H$3:$H$1022,Снабжения!$A$3:$A$1022,">=01.12.2025",Снабжения!$A$3:$A$1022,"<=31.12.2025") -> 0 | D4: =SUMIFS(Снабжения!$H$3:$H$1022,Снабжения!$A$3:$A$1022,">=01.02.2026",Снабжения!$A$3:$A$1022,"<=28.02.2026") -> 83209644 | E4: =SUMIFS(Снабжения!$H$3:$H$1022,Снабжения!$A$3:$A$1022,">=01.03.2026",Снабжения!$A$3:$A$1022,"<=31.03.2026") -> 48394067 | F4: =SUMIFS(Снабжения!$H$3:$H$1022,Снабжения!$A$3:$A$1022,">=01.04.2026",Снабжения!$A$3:$A$1022,"<=30.04.2026") -> 47268860 | G4: =SUMIFS(Снабжения!$H$3:$H$1022,Снабжения!$A$3:$A$1022,">=01.05.2026",Снабжения!$A$3:$A$1022,"<=31.05.2026") -> 46954138 | H4: =SUMIFS(Снабжения!$H$3:$H$1022,Снабжения!$A$3:$A$1022,">=01.06.2026",Снабжения!$A$3:$A$1022,"<=30.06.2026") -> 0
A5: Арматура | B5: =SUMIFS('Арматура приход'!$AB$2:$AB$192,'Арматура приход'!$B$2:$B$192,">=01.11.2025",'Арматура приход'!$B$2:$B$192,"<=30.11.2025") -> 8.4335567e+08 | C5: =SUMIFS('Арматура приход'!$AB$2:$AB$192,'Арматура приход'!$B$2:$B$192,">=01.12.2025",'Арматура приход'!$B$2:$B$192,"<=31.12.2025") -> 0 | D5: =SUMIFS('Арматура приход'!$AB$2:$AB$192,'Арматура приход'!$B$2:$B$192,">=01.02.2026",'Арматура приход'!$B$2:$B$192,"<=28.02.2026") -> 1344752928 | E5: =SUMIFS('Арматура приход'!$AB$2:$AB$192,'Арматура приход'!$B$2:$B$192,">=01.03.2026",'Арматура приход'!$B$2:$B$192,"<=31.03.2026") -> 571152608 | F5: =SUMIFS('Арматура приход'!$AB$2:$AB$192,'Арматура приход'!$B$2:$B$192,">=01.04.2026",'Арматура приход'!$B$2:$B$192,"<=30.04.2026") -> 1175574400 | G5: =SUMIFS('Арматура приход'!$AB$2:$AB$300,'Арматура приход'!$B$2:$B$300,">=01.05.2026",'Арматура приход'!$B$2:$B$300,"<=31.05.2026") -> 1343005248 | H5: =SUMIFS('Арматура приход'!$AB$2:$AB$300,'Арматура приход'!$B$2:$B$300,">=01.06.2026",'Арматура приход'!$B$2:$B$300,"<=30.06.2026") -> 0
A6: Бетон | B6: =SUMIFS(Бетон!$F:$F,Бетон!$A:$A,">=01.11.2025",Бетон!$A:$A,"<=30.11.2025") -> 95090000 | C6: =SUMIFS(Бетон!$F:$F,Бетон!$A:$A,">=01.12.2025",Бетон!$A:$A,"<=31.12.2025") -> 0 | D6: =SUMIFS(Бетон!$F:$F,Бетон!$A:$A,">=01.02.2026",Бетон!$A:$A,"<=28.02.2026") -> 1837510000 | E6: =SUMIFS(Бетон!$F:$F,Бетон!$A:$A,">=01.03.2026",Бетон!$A:$A,"<=31.03.2026") -> 618770000 | F6: =SUMIFS(Бетон!$F:$F,Бетон!$A:$A,">=01.04.2026",Бетон!$A:$A,"<=30.04.2026") -> 752500000 | G6: =SUMIFS(Бетон!$F:$F,Бетон!$A:$A,">=01.05.2026",Бетон!$A:$A,"<=31.05.2026") -> 811300000 | H6: =SUMIFS(Бетон!$F:$F,Бетон!$A:$A,">=01.06.2026",Бетон!$A:$A,"<=30.06.2026") -> 151200000
A7: Опалубка | B7: =SUMIFS(Строй.Мат!$M$2:$M$1010,Строй.Мат!$A$2:$A$1010,">=01.11.2025",Строй.Мат!$A$2:$A$1010,"<=30.11.2025") -> 7100000 | C7: =SUMIFS(Строй.Мат!$M$2:$M$1010,Строй.Мат!$A$2:$A$1010,">=01.12.2025",Строй.Мат!$A$2:$A$1010,"<=31.12.2025") -> 0 | D7: =SUMIFS(Строй.Мат!$M$2:$M$1010,Строй.Мат!$A$2:$A$1010,">=01.02.2026",Строй.Мат!$A$2:$A$1010,"<=28.02.2026") -> 0 | E7: =SUMIFS(Строй.Мат!$M$2:$M$1010,Строй.Мат!$A$2:$A$1010,">=01.03.2026",Строй.Мат!$A$2:$A$1010,"<=31.03.2026") -> 676731600 | F7: =SUMIFS(Строй.Мат!$M$2:$M$1010,Строй.Мат!$A$2:$A$1010,">=01.04.2026",Строй.Мат!$A$2:$A$1010,"<=30.04.2026") -> 1419436000 | G7: =SUMIFS(Строй.Мат!$M$2:$M$1010,Строй.Мат!$A$2:$A$1010,">=01.05.2026",Строй.Мат!$A$2:$A$1010,"<=31.05.2026") -> 8300000 | H7: =SUMIFS(Строй.Мат!$M$2:$M$1010,Строй.Мат!$A$2:$A$1010,">=01.06.2026",Строй.Мат!$A$2:$A$1010,"<=30.06.2026") -> 28500000
A8: Учет Расходов | B8: =SUMIFS(Расходы!$J$2:$J$1000,Расходы!$A$2:$A$1000,">=01.11.2025",Расходы!$A$2:$A$1000,"<=30.11.2025") -> 0 | C8: =SUMIFS(Расходы!$J$2:$J$1000,Расходы!$A$2:$A$1000,">=01.12.2025",Расходы!$A$2:$A$1000,"<=31.12.2025") -> 0 | D8: =SUMIFS(Расходы!$J$2:$J$1000,Расходы!$A$2:$A$1000,">=01.02.2026",Расходы!$A$2:$A$1000,"<=28.02.2026") -> 86333494 | E8: =SUMIFS(Расходы!$J$2:$J$1000,Расходы!$A$2:$A$1000,">=01.03.2026",Расходы!$A$2:$A$1000,"<=31.03.2026") -> 8778300 | F8: =SUMIFS(Расходы!$J$2:$J$1000,Расходы!$A$2:$A$1000,">=01.04.2026",Расходы!$A$2:$A$1000,"<=30.04.2026") -> 6895500 | G8: =SUMIFS(Расходы!$J$2:$J$1000,Расходы!$A$2:$A$1000,">=01.05.2026",Расходы!$A$2:$A$1000,"<=31.05.2026") -> 0 | H8: =SUMIFS(Расходы!$J$2:$J$1000,Расходы!$A$2:$A$1000,">=01.06.2026",Расходы!$A$2:$A$1000,"<=30.06.2026") -> 12000000
A9: Арматура тоннаж | B9: =B18/640 -> 110.444 | C9: =C18/640 -> 0 | D9: =D18/640 -> 173.425 | E9: =E18/640 -> 73.825 | F9: =F18/640 -> 151.96 | G9: =G18/640 -> 274.9 | H9: =H18/640 -> 0
A10: Бозорлик | B10: =SUMIFS(Бозорлик!$F$2:$F$1002,Бозорлик!$A$2:$A$1002,">=01.11.2025",Бозорлик!$A$2:$A$1002,"<=30.11.2025") -> 850000 | C10: =SUMIFS(Бозорлик!$F$2:$F$1002,Бозорлик!$A$2:$A$1002,">=01.12.2025",Бозорлик!$A$2:$A$1002,"<=31.12.2025") -> 0 | D10: =SUMIFS(Бозорлик!$F$2:$F$1002,Бозорлик!$A$2:$A$1002,">=01.02.2026",Бозорлик!$A$2:$A$1002,"<=28.02.2026") -> 17507440 | E10: =SUMIFS(Бозорлик!$F$2:$F$1002,Бозорлик!$A$2:$A$1002,">=01.03.2026",Бозорлик!$A$2:$A$1002,"<=31.03.2026") -> 24949046 | F10: =SUMIFS(Бозорлик!$F$2:$F$1002,Бозорлик!$A$2:$A$1002,">=01.04.2026",Бозорлик!$A$2:$A$1002,"<=30.04.2026") -> 29292191 | G10: =SUMIFS(Бозорлик!$F$2:$F$1002,Бозорлик!$A$2:$A$1002,">=01.05.2026",Бозорлик!$A$2:$A$1002,"<=31.05.2026") -> 40428150 | H10: =SUMIFS(Бозорлик!$F$2:$F$1002,Бозорлик!$A$2:$A$1002,">=01.06.2026",Бозорлик!$A$2:$A$1002,"<=30.06.2026") -> 3285000
A11: Спец.Техника | B11: =SUMIFS(Спец.Техника!$F$2:$F$1018,Спец.Техника!$A$2:$A$1018,">=01.11.2025",Спец.Техника!$A$2:$A$1018,"<=30.11.2025") -> 0 | C11: =SUMIFS(Спец.Техника!$F$2:$F$1018,Спец.Техника!$A$2:$A$1018,">=01.12.2025",Спец.Техника!$A$2:$A$1018,"<=31.12.2025") -> 0 | D11: =SUMIFS(Спец.Техника!$F$2:$F$1018,Спец.Техника!$A$2:$A$1018,">=01.02.2026",Спец.Техника!$A$2:$A$1018,"<=28.02.2026") -> 48390000 | E11: =SUMIFS(Спец.Техника!$F$2:$F$1018,Спец.Техника!$A$2:$A$1018,">=01.03.2026",Спец.Техника!$A$2:$A$1018,"<=31.03.2026") -> 3500000 | F11: =SUMIFS(Спец.Техника!$F$2:$F$1018,Спец.Техника!$A$2:$A$1018,">=01.04.2026",Спец.Техника!$A$2:$A$1018,"<=30.04.2026") -> 2000000 | G11: =SUMIFS(Спец.Техника!$F$2:$F$1018,Спец.Техника!$A$2:$A$1018,">=01.05.2026",Спец.Техника!$A$2:$A$1018,"<=31.05.2026") -> 0 | H11: =SUMIFS(Спец.Техника!$F$2:$F$1018,Спец.Техника!$A$2:$A$1018,">=01.05.2026",Спец.Техника!$A$2:$A$1018,"<=31.05.2026") -> 0
A12: Итого | B12: =SUM(B3:B8,B10,B11) -> 1.0725847e+09 | C12: =SUM(C3:C8,C10,C11) -> 0 | D12: =SUM(D3:D8,D10,D11) -> 3825233506 | E12: =SUM(E3:E8,E10,E11) -> 2.4114556e+09 | F12: =SUM(F3:F8,F10,F11) -> 3.432967e+09 | G12: =SUM(G3:G8,G10,G11) -> 2.9532675e+09 | H12: =SUM(H3:H8) -> 1128810000 | I12: =SUM(I3:I8) -> 0 | J12: =SUM(J3:J8) -> 0 | K12: =SUM(K3:K8) -> 0 | L12: =SUM(L3:L8) -> 0 | M12: =SUM(M3:M8) -> 0 | N12: =SUM(N3:N8) -> 0
A14: СВОДКА ПО МЕСЯЦАМ — ТОННАЖИ И ОБЪЁМЫ
A15: Категория | B15: 2025г.Ноябрь | C15: 2025г.Декабрь | D15: 2026г.Февраль | E15: 2026г.Март | F15: 2026г.Апрель | G15: 2026г.Май | H15: 2026г.Июнь | I15: 2026г.Июль | J15: Август | K15: Сентябрь | L15: Октябрь | M15: Ноябрь | N15: Декабрь
A16: Оплата рабочих | B16: =SUMIFS('Оплата рабочих'!$G$2:$G$115,'Оплата рабочих'!$A$2:$A$115,">=01.11.2025",'Оплата рабочих'!$A$2:$A$115,"<=30.11.2025") -> 7641.25 | C16: =SUMIFS('Оплата рабочих'!$G$2:$G$115,'Оплата рабочих'!$A$2:$A$115,">=01.12.2025",'Оплата рабочих'!$A$2:$A$115,"<=31.12.2025") -> 0 | D16: =SUMIFS('Оплата рабочих'!$G$2:$G$115,'Оплата рабочих'!$A$2:$A$115,">=01.02.2026",'Оплата рабочих'!$A$2:$A$115,"<=28.02.2026") -> 33705.8 | E16: =SUMIFS('Оплата рабочих'!$G$2:$G$115,'Оплата рабочих'!$A$2:$A$115,">=01.03.2026",'Оплата рабочих'!$A$2:$A$115,"<=31.03.2026") -> 37854.905 | F16: =SUMIFS('Оплата рабочих'!$G$2:$G$115,'Оплата рабочих'!$A$2:$A$115,">=01.04.2026",'Оплата рабочих'!$A$2:$A$115,"<=30.04.2026") -> 0 | G16: =SUMIFS('Оплата рабочих'!$G$2:$G$115,'Оплата рабочих'!$A$2:$A$115,">=01.05.2026",'Оплата рабочих'!$A$2:$A$115,"<=31.05.2026") -> 58331.185 | H16: =SUMIFS('Оплата рабочих'!$G$2:$G$115,'Оплата рабочих'!$A$2:$A$115,">=01.06.2026",'Оплата рабочих'!$A$2:$A$115,"<=30.06.2026") -> #DIV/0!
A17: Строй Хоз.Товар | B17: {=SUMPRODUCT((Снабжения!$A$3:$A$1031>=DATE(2025,11,1))*(Снабжения!$A$3:$A$1031<=DATE(2025,11,30))*IFERROR(Снабжения!$P$3:$P$1031*1,0))} -> 2871.8605 | C17: {=SUMPRODUCT((Снабжения!$A$3:$A$1031>=DATE(2025,12,1))*(Снабжения!$A$3:$A$1031<=DATE(2025,12,31))*IFERROR(Снабжения!$P$3:$P$1031*1,0))} -> 0 | D17: {=SUMPRODUCT((Снабжения!$A$3:$A$1031>=DATE(2026,2,1))*(Снабжения!$A$3:$A$1031<=DATE(2026,2,28))*IFERROR(Снабжения!$P$3:$P$1031*1,0))} -> 6859.6783 | E17: {=SUMPRODUCT((Снабжения!$A$3:$A$1031>=DATE(2026,3,1))*(Снабжения!$A$3:$A$1031<=DATE(2026,3,31))*IFERROR(Снабжения!$P$3:$P$1031*1,0))} -> 4004.5189 | F17: {=SUMPRODUCT((Снабжения!$A$3:$A$1031>=DATE(2026,4,1))*(Снабжения!$A$3:$A$1031<=DATE(2026,4,30))*IFERROR(Снабжения!$P$3:$P$1031*1,0))} -> 3913.6016 | G17: {=SUMPRODUCT((Снабжения!$A$3:$A$1031>=DATE(2026,5,1))*(Снабжения!$A$3:$A$1031<=DATE(2026,5,31))*IFERROR(Снабжения!$P$3:$P$1031*1,0))} -> 2737.9202 | H17: =SUMIFS(Снабжения!$P$3:$P$1022,Снабжения!$A$3:$A$1022,">=01.06.2026",Снабжения!$A$3:$A$1022,"<=30.06.2026") -> #DIV/0!
A18: Арматура | B18: =SUMIFS('Арматура приход'!$AD$2:$AD$192,'Арматура приход'!$B$2:$B$192,">=01.11.2025",'Арматура приход'!$B$2:$B$192,"<=30.11.2025") -> 70684.16 | C18: =SUMIFS('Арматура приход'!$X$2:$X$192,'Арматура приход'!$B$2:$B$192,">=01.12.2025",'Арматура приход'!$B$2:$B$192,"<=31.12.2025") -> 0 | D18: =SUMIFS('Арматура приход'!$AD$2:$AD$192,'Арматура приход'!$B$2:$B$192,">=01.02.2026",'Арматура приход'!$B$2:$B$192,"<=28.02.2026") -> 110992 | E18: =SUMIFS('Арматура приход'!$AD$2:$AD$192,'Арматура приход'!$B$2:$B$192,">=01.03.2026",'Арматура приход'!$B$2:$B$192,"<=31.03.2026") -> 47248 | F18: =SUMIFS('Арматура приход'!$AD$2:$AD$300,'Арматура приход'!$B$2:$B$300,">=01.04.2026",'Арматура приход'!$B$2:$B$300,"<=30.04.2026") -> 97254.4 | G18: =SUMIFS('Арматура приход'!$AD$2:$AD$300,'Арматура приход'!$B$2:$B$300,">=01.05.2026",'Арматура приход'!$B$2:$B$300,"<=31.05.2026") -> 175936 | H18: =SUMIFS('Арматура приход'!$AD$2:$AD$300,'Арматура приход'!$B$2:$B$300,">=01.06.2026",'Арматура приход'!$B$2:$B$300,"<=30.06.2026") -> 0
A19: Бетон | B19: =SUMIFS(Бетон!$G:$G,Бетон!$A:$A,">=01.11.2025",Бетон!$A:$A,"<=30.11.2025") -> 8067.6651 | C19: =SUMIFS(Бетон!$G:$G,Бетон!$A:$A,">=01.12.2025",Бетон!$A:$A,"<=31.12.2025") -> 0 | D19: =SUMIFS(Бетон!$G:$G,Бетон!$A:$A,">=01.02.2026",Бетон!$A:$A,"<=28.02.2026") -> 152166.81 | E19: =SUMIFS(Бетон!$G:$G,Бетон!$A:$A,">=01.03.2026",Бетон!$A:$A,"<=31.03.2026") -> 51029.593 | F19: =SUMIFS(Бетон!$G:$G,Бетон!$A:$A,">=01.04.2026",Бетон!$A:$A,"<=30.04.2026") -> 62402.971 | G19: {=SUMPRODUCT((Бетон!$A$2:$A$1086>=DATE(2026,5,1))*(Бетон!$A$2:$A$1086<=DATE(2026,5,31))*IFERROR(Бетон!$G$2:$G$1086*1,0))} -> 53347.41 | H19: =SUMIFS(Бетон!$G:$G,Бетон!$A:$A,">=01.06.2026",Бетон!$A:$A,"<=30.06.2026") -> #DIV/0!
A20: Опалубка | B20: =SUMIFS(Строй.Мат!$P$2:$P$1010,Строй.Мат!$A$2:$A$1010,">=01.11.2025",Строй.Мат!$A$2:$A$1010,"<=30.11.2025") -> 3175.0841 | C20: =SUMIFS(Строй.Мат!$P$2:$P$1010,Строй.Мат!$A$2:$A$1010,">=01.12.2025",Строй.Мат!$A$2:$A$1010,"<=31.12.2025") -> 0 | D20: =SUMIFS(Строй.Мат!$P$2:$P$1010,Строй.Мат!$A$2:$A$1010,">=01.02.2026",Строй.Мат!$A$2:$A$1010,"<=28.02.2026") -> 631.14754 | E20: =SUMIFS(Строй.Мат!$P$2:$P$1010,Строй.Мат!$A$2:$A$1010,">=01.03.2026",Строй.Мат!$A$2:$A$1010,"<=31.03.2026") -> 56295.481 | F20: =SUMIFS(Строй.Мат!$P$2:$P$1010,Строй.Мат!$A$2:$A$1010,">=01.04.2026",Строй.Мат!$A$2:$A$1010,"<=30.04.2026") -> 120399.7 | G20: =SUMIFS(Строй.Мат!$P$2:$P$1010,Строй.Мат!$A$2:$A$1010,">=01.05.2026",Строй.Мат!$A$2:$A$1010,"<=31.05.2026") -> #DIV/0! | H20: =SUMIFS(Строй.Мат!$P$2:$P$1010,Строй.Мат!$A$2:$A$1010,">=01.06.2026",Строй.Мат!$A$2:$A$1010,"<=30.06.2026") -> #DIV/0!
A21: Учет Расходов | B21: {=SUMPRODUCT((Расходы!$A$2:$A$1000>=DATE(2025,11,1))*(Расходы!$A$2:$A$1000<=DATE(2025,11,30))*IFERROR(Расходы!$N$2:$N$1000*1,0))} -> 0 | C21: {=SUMPRODUCT((Расходы!$A$2:$A$1000>=DATE(2025,12,1))*(Расходы!$A$2:$A$1000<=DATE(2025,12,31))*IFERROR(Расходы!$N$2:$N$1000*1,0))} -> 0 | D21: {=SUMPRODUCT((Расходы!$A$2:$A$1000>=DATE(2026,2,1))*(Расходы!$A$2:$A$1000<=DATE(2026,2,28))*IFERROR(Расходы!$N$2:$N$1000*1,0))} -> 7140.7653 | E21: {=SUMPRODUCT((Расходы!$A$2:$A$1000>=DATE(2026,3,1))*(Расходы!$A$2:$A$1000<=DATE(2026,3,31))*IFERROR(Расходы!$N$2:$N$1000*1,0))} -> 728.08768 | F21: {=SUMPRODUCT((Расходы!$A$2:$A$1000>=DATE(2026,4,1))*(Расходы!$A$2:$A$1000<=DATE(2026,4,30))*IFERROR(Расходы!$N$2:$N$1000*1,0))} -> 571.28733 | G21: {=SUMPRODUCT((Расходы!$A$2:$A$1000>=DATE(2026,5,1))*(Расходы!$A$2:$A$1000<=DATE(2026,5,31))*IFERROR(Расходы!$N$2:$N$1000*1,0))} -> 0 | H21: =SUMIFS(Расходы!$N$2:$N$1000,Расходы!$A$2:$A$1000,">=01.06.2026",Расходы!$A$2:$A$1000,"<=30.06.2026") -> #DIV/0!
A22: Арматура тоннаж | B22: =B18/640 -> 110.444 | C22: =C18/640 -> 0 | D22: =D18/640 -> 173.425 | E22: =E18/640 -> 73.825 | F22: =F18/640 -> 151.96 | G22: =G18/640 -> 274.9 | H22: =H18/640 -> 0
A23: Бозорлик | B23: =SUMIFS(Бозорлик!$G$2:$G$1014,Бозорлик!$A$2:$A$1014,">=01.11.2025",Бозорлик!$A$2:$A$1014,"<=30.11.2025") -> 73.275862 | C23: =SUMIFS(Бозорлик!$G$2:$G$1014,Бозорлик!$A$2:$A$1014,">=01.12.2025",Бозорлик!$A$2:$A$1014,"<=31.12.2025") -> 0 | D23: =SUMIFS(Бозорлик!$G$2:$G$1014,Бозорлик!$A$2:$A$1014,">=01.02.2026",Бозорлик!$A$2:$A$1014,"<=28.02.2026") -> 1442.9119 | E23: =SUMIFS(Бозорлик!$G$2:$G$1014,Бозорлик!$A$2:$A$1014,">=01.03.2026",Бозорлик!$A$2:$A$1014,"<=31.03.2026") -> 2062.8628 | F23: =SUMIFS(Бозорлик!$G$2:$G$1014,Бозорлик!$A$2:$A$1014,">=01.04.2026",Бозорлик!$A$2:$A$1014,"<=30.04.2026") -> 2414.8633 | G23: {=SUMPRODUCT((Бозорлик!$A$2:$A$1014>=DATE(2026,5,1))*(Бозорлик!$A$2:$A$1014<=DATE(2026,5,31))*IFERROR(Бозорлик!$G$2:$G$1014*1,0))} -> 2439.3399 | H23: =SUMIFS(Бозорлик!$G$2:$G$1014,Бозорлик!$A$2:$A$1014,">=01.06.2026",Бозорлик!$A$2:$A$1014,"<=30.06.2026") -> #DIV/0!
A24: Спец.Техника | B24: =SUMIFS(Спец.Техника!$G$2:$G$1030,Спец.Техника!$A$2:$A$1030,">=01.11.2025",Спец.Техника!$A$2:$A$1030,"<=30.11.2025") -> 0 | C24: =SUMIFS(Спец.Техника!$G$2:$G$1030,Спец.Техника!$A$2:$A$1030,">=01.12.2025",Спец.Техника!$A$2:$A$1030,"<=31.12.2025") -> 0 | D24: =SUMIFS(Спец.Техника!$G$2:$G$1030,Спец.Техника!$A$2:$A$1030,">=01.02.2026",Спец.Техника!$A$2:$A$1030,"<=28.02.2026") -> 3964.9068 | E24: =SUMIFS(Спец.Техника!$G$2:$G$1030,Спец.Техника!$A$2:$A$1030,">=01.03.2026",Спец.Техника!$A$2:$A$1030,"<=31.03.2026") -> 289.21529 | F24: =SUMIFS(Спец.Техника!$G$2:$G$1030,Спец.Техника!$A$2:$A$1030,">=01.04.2026",Спец.Техника!$A$2:$A$1030,"<=30.04.2026") -> 164.60905 | G24: =SUMIFS(Спец.Техника!$G$2:$G$1030,Спец.Техника!$A$2:$A$1030,">=01.05.2026",Спец.Техника!$A$2:$A$1030,"<=31.05.2026") -> 0 | H24: =SUMIFS(Спец.Техника!$G$2:$G$1030,Спец.Техника!$A$2:$A$1030,">=01.06.2026",Спец.Техника!$A$2:$A$1030,"<=30.06.2026") -> 0
A25: Итого | B25: =SUM(B16:B21,B23:B24) -> 92513.296 | C25: =SUM(C16:C21,C23:C24) -> 0 | D25: =SUM(D16:D21,D23:D24) -> 316904.02 | E25: =SUM(E16:E21,E23:E24) -> 199512.66 | F25: =SUM(F16:F21,F23:F24) -> 287121.43 | G25: =SUM(G16:G21,G23:G24) -> #DIV/0! | H25: =SUM(H16:H21) -> #DIV/0! | I25: =SUM(I16:I21) -> 0 | J25: =SUM(J16:J21) -> 0 | K25: =SUM(K16:K21) -> 0 | L25: =SUM(L16:L21) -> 0 | M25: =SUM(M16:M21) -> 0 | N25: =SUM(N16:N21) -> 0

Sheet Курс валют
A1: Дата | B1: Валюта | C1: Количество | D1: Курс (сум)
A2: 45962 | B2: USD | C2: 1 | D2: 12100
A3: 45963 | B3: USD | C3: 1 | D3: 11970
A4: 45964 | B4: USD | C4: 1 | D4: 11970
A5: 45968 | B5: USD | C5: 1 | D5: 12020
A6: 45973 | B6: USD | C6: 1 | D6: 12000
A7: 45978 | B7: USD | C7: 1 | D7: 11800
A8: 45986 | B8: USD | C8: 1 | D8: 11600
A9: 45990 | B9: USD | C9: 1 | D9: 11600
A10: 46054 | B10: USD | C10: 1 | D10: 12200
A11: 46055 | B11: USD | C11: 1 | D11: 12200
A12: 46056 | B12: USD | C12: 1 | D12: 12200
A13: 46057 | B13: USD | C13: 1 | D13: 12200
... A119: 46163 | B119: USD | C119: 1 | D119: 12130
A120: 46164 | B120: USD | C120: 1
A121: 46165 | B121: USD | C121: 1
A122: 46166 | B122: USD | C122: 1
A123: 46167 | B123: USD | C123: 1
A124: 46168 | B124: USD | C124: 1
A125: 46169 | B125: USD | C125: 1
A126: 46170 | B126: USD | C126: 1
A127: 46171 | B127: USD | C127: 1
A128: 46172 | B128: USD | C128: 1
A129: 46173 | B129: USD | C129: 1
A130: 46174 | B130: USD | C130: 1
A131: 46175 | B131: USD | C131: 1
... A147: 46191 | B147: USD | C147: 1

Sheet Оплата рабочих
A1: Дата | B1: № | C1: Наименование товара | D1: Ед.изм | E1: Кол-во | F1: Сумма | G1: В долларе | H1: Заказчик
A2: 45973 | B2: 1 | C2: Услуга рабочих изоляций | D2: м2 | E2: 1 | F2: 91695000 | G2: =IF(A2<>"", F2 / VLOOKUP(A2, 'Курс валют'!$A:$D, 4, 0), "") -> 7641.25 | H2: Мева Шарбат Илмий Экспериментал Виночилик
A3: 12.11.2025 Итог | F3: =SUBTOTAL(9,F2:F2) -> 91695000 | G3: =IF(A3<>"", F3 / VLOOKUP(A3, 'Курс валют'!$A:$D, 4, 0), "") -> #N/A
A4: 46054 | B4: 1 | C4: Технадзор | D4: зарплата | E4: 1 | F4: 6000000 | G4: =IF(A4<>"", F4 / VLOOKUP(A4, 'Курс валют'!$A:$D, 4, 0), "") -> 491.80328 | H4: Мева Шарбат Илмий Экспериментал Виночилик
A5: 46054 | B5: 2 | C5: Геодезист | D5: зарплата | E5: 1 | F5: 7000000 | G5: =IF(A5<>"", F5 / VLOOKUP(A5, 'Курс валют'!$A:$D, 4, 0), "") -> 573.77049 | H5: Мева Шарбат Илмий Экспериментал Виночилик
A6: 46054 | B6: 3 | C6: Прораб | D6: зарплата | E6: 1 | F6: 10000000 | G6: =IF(A6<>"", F6 / VLOOKUP(A6, 'Курс валют'!$A:$D, 4, 0), "") -> 819.67213 | H6: Мева Шарбат Илмий Экспериментал Виночилик
A7: 46054 | B7: 4 | C7: ТБ и ОТ | D7: зарплата | E7: 1 | F7: 4000000 | G7: =IF(A7<>"", F7 / VLOOKUP(A7, 'Курс валют'!$A:$D, 4, 0), "") -> 327.86885 | H7: Мева Шарбат Илмий Экспериментал Виночилик
A8: 46054 | B8: 5 | C8: Крановщик | D8: зарплата | E8: 1 | F8: 10000000 | G8: =IF(A8<>"", F8 / VLOOKUP(A8, 'Курс валют'!$A:$D, 4, 0), "") -> 819.67213 | H8: Мева Шарбат Илмий Экспериментал Виночилик
A9: 01.02.2026 Итог | F9: =SUBTOTAL(9,F4:F8) -> 37000000 | G9: =IF(A9<>"", F9 / VLOOKUP(A9, 'Курс валют'!$A:$D, 4, 0), "") -> #N/A
A10: 46081 | B10: 1 | C10: Бетон | D10: м2 | E10: 2414 | F10: =145000*E10 -> 350030000 | G10: =IF(A10<>"", F10 / VLOOKUP(A10, 'Курс валют'!$A:$D, 4, 0), "") -> 28975.993 | H10: Мева Шарбат Илмий Экспериментал Виночилик
A11: 46081 | B11: 2 | C11: Вертолет | D11: м2 | E11: 2050 | F11: =10000*E11 -> 20500000 | G11: =IF(A11<>"", F11 / VLOOKUP(A11, 'Курс валют'!$A:$D, 4, 0), "") -> 1697.0199 | H11: Мева Шарбат Илмий Экспериментал Виночилик
A12: 28.02.2026 Итог | F12: =SUBTOTAL(9,F10:F11) -> 370530000 | G12: =IF(A12<>"", F12 / VLOOKUP(A12, 'Курс валют'!$A:$D, 4, 0), "") -> #N/A
A13: 46112 | B13: 1 | C13: Бетон | D13: м2 | E13: 3530 | F13: =E13*115000 -> 405950000 | G13: =IF(A13<>"", F13 / VLOOKUP(A13, 'Курс валют'!$A:$D, 4, 0), "") -> 33466.612 | H13: Мева Шарбат Илмий Экспериментал Виночилик
A14: 46112 | B14: 2 | C14: Вертолет | D14: м2 | E14: 923 | F14: =10000*E14 -> 9230000 | G14: =IF(A14<>"", F14 / VLOOKUP(A14, 'Курс валют'!$A:$D, 4, 0), "") -> 760.92333 | H14: Мева Шарбат Илмий Экспериментал Виночилик
A15: 46112 | B15: 3 | C15: Технадзор | D15: зарплата | E15: 1 | F15: 6000000 | G15: =IF(A15<>"", F15 / VLOOKUP(A15, 'Курс валют'!$A:$D, 4, 0), "") -> 494.64138 | H15: Мева Шарбат Илмий Экспериментал Виночилик
A16: 46112 | B16: 4 | C16: Геодезист | D16: зарплата | E16: 1 | F16: 7000000 | G16: =IF(A16<>"", F16 / VLOOKUP(A16, 'Курс валют'!$A:$D, 4, 0), "") -> 577.08162 | H16: Мева Шарбат Илмий Экспериментал Виночилик
A17: 46112 | B17: 5 | C17: Прораб | D17: зарплата | E17: 1 | F17: 10000000 | G17: =IF(A17<>"", F17 / VLOOKUP(A17, 'Курс валют'!$A:$D, 4, 0), "") -> 824.40231 | H17: Мева Шарбат Илмий Экспериментал Виночилик
A18: 46112 | B18: 6 | C18: ТБ и ОТ | D18: зарплата | E18: 1 | F18: 4000000 | G18: =IF(A18<>"", F18 / VLOOKUP(A18, 'Курс валют'!$A:$D, 4, 0), "") -> 329.76092 | H18: Мева Шарбат Илмий Экспериментал Виночилик
A19: 46112 | B19: 7 | C19: Крановщик | D19: зарплата | E19: 1 | F19: 12000000 | G19: =IF(A19<>"", F19 / VLOOKUP(A19, 'Курс валют'!$A:$D, 4, 0), "") -> 989.28277 | H19: Мева Шарбат Илмий Экспериментал Виночилик
A20: 46112 | B20: 8 | C20: Повар | D20: зарплата | E20: 1 | F20: 5000000 | G20: =IF(A20<>"", F20 / VLOOKUP(A20, 'Курс валют'!$A:$D, 4, 0), "") -> 412.20115 | H20: Мева Шарбат Илмий Экспериментал Виночилик
A21: 31.03.2026 Итог | F21: =SUBTOTAL(9,F13:F20) -> 459180000 | G21: =IF(A21<>"", F21 / VLOOKUP(A21, 'Курс валют'!$A:$D, 4, 0), "") -> #N/A
A22: Общий итог | F22: =SUBTOTAL(9,F2:F20) -> 958405000 | G22: =IF(A22<>"", F22 / VLOOKUP(A22, 'Курс валют'!$A:$D, 4, 0), "") -> #N/A
A23: 46143 | B23: 1 | C23: Бетон | D23: м2 | F23: 400000000 | G23: =IF(A23<>"", F23 / VLOOKUP(A23, 'Курс валют'!$A:$D, 4, 0), "") -> 33057.851 | H23: Мева Шарбат Илмий Экспериментал Виночилик
A24: 46146 | B24: 2 | C24: Бетон | D24: м2 | F24: 170000000 | G24: =IF(A24<>"", F24 / VLOOKUP(A24, 'Курс валют'!$A:$D, 4, 0), "") -> 14166.667 | H24: Мева Шарбат Илмий Экспериментал Виночилик
A25: 46147 | B25: 3 | C25: Бетон | D25: м2 | F25: 133280000 | G25: =IF(A25<>"", F25 / VLOOKUP(A25, 'Курс валют'!$A:$D, 4, 0), "") -> 11106.667 | H25: Мева Шарбат Илмий Экспериментал Виночилик
A26: 46174 | B26: 1 | C26: Бетон | D26: м2 | F26: 450000000 | G26: =IF(A26<>"", F26 / VLOOKUP(A26, 'Курс валют'!$A:$D, 4, 0), "") -> #DIV/0! | H26: Мева Шарбат Илмий Экспериментал Виночилик
A27: 46176 | B27: 1 | C27: Бетон | D27: м2 | F27: 350000000 | G27: =IF(A27<>"", F27 / VLOOKUP(A27, '[1]Курс валют'!$A:$D, 4, 0), "") -> #DIV/0! | H27: Мева Шарбат Илмий Экспериментал Виночилик
A28: 46176 | B28: 2 | C28: Изоляция | D28: м2 | F28: 3360000 | G28: =IF(A28<>"", F28 / VLOOKUP(A28, '[1]Курс валют'!$A:$D, 4, 0), "") -> #DIV/0! | H28: Мева Шарбат Илмий Экспериментал Виночилик
A29: 46178 | B29: 1 | C29: Бетон | D29: м2 | F29: 133750000 | G29: =IF(A29<>"", F29 / VLOOKUP(A29, '[1]Курс валют'!$A:$D, 4, 0), "") -> #DIV/0! | H29: Мева Шарбат Илмий Экспериментал Виночилик
G30: =IF(A30<>"", F30 / VLOOKUP(A30, '[1]Курс валют'!$A:$D, 4, 0), "")

Sheet Бозорлик
A1: Дата | B1: Наименование | C1: Ед.изм | D1: Кол-во | E1: Сумма за ед.изм | F1: Общая | G1: В долларе | H1: Столбец1
A2: 45986 | B2: Сабзи | C2: кг | D2: 60 | E2: 7000 | F2: =[1]Бозорлик!$D2*[1]Бозорлик!$E2 -> 420000 | G2: =IF(A2<>"", F2/ VLOOKUP(A2, 'Курс валют'!$A:$D, 4, 0), "") -> 36.206897
A3: 45986 | B3: Пиёз | C3: кг | D3: 35 | E3: 4000 | F3: =[1]Бозорлик!$D3*[1]Бозорлик!$E3 -> 140000 | G3: =IF(A3<>"", F3/ VLOOKUP(A3, 'Курс валют'!$A:$D, 4, 0), "") -> 12.068966
A4: 45986 | B4: Ёг | C4: литр | D4: 10 | E4: 21000 | F4: =[1]Бозорлик!$D4*[1]Бозорлик!$E4 -> 210000 | G4: =IF(A4<>"", F4/ VLOOKUP(A4, 'Курс валют'!$A:$D, 4, 0), "") -> 18.103448
A5: 45986 | B5: Туруп | C5: кг | D5: 10 | E5: 7000 | F5: =[1]Бозорлик!$D5*[1]Бозорлик!$E5 -> 70000 | G5: =IF(A5<>"", F5/ VLOOKUP(A5, 'Курс валют'!$A:$D, 4, 0), "") -> 6.0344828
A6: 45986 | B6: Арава | C6: услуга | D6: 1 | E6: 10000 | F6: =[1]Бозорлик!$D6*[1]Бозорлик!$E6 -> 10000 | G6: =IF(A6<>"", F6/ VLOOKUP(A6, 'Курс валют'!$A:$D, 4, 0), "") -> 0.86206897
A7: 25.11.2025 Итог | F7: =SUBTOTAL(9,F2:F6) -> 850000 | G7: =IF(A7<>"", F7/ VLOOKUP(A7, 'Курс валют'!$A:$D, 4, 0), "") -> #N/A
A8: 46060 | B8: Пахта ёг | C8: литр | D8: 10 | E8: 20000 | F8: =[1]Бозорлик!$D8*[1]Бозорлик!$E8 -> 200000 | G8: =IF(A8<>"", F8/ VLOOKUP(A8, 'Курс валют'!$A:$D, 4, 0), "") -> 16.393443
A9: 46060 | B9: Томат | C9: шт | D9: 3 | E9: 30000 | F9: =[1]Бозорлик!$D9*[1]Бозорлик!$E9 -> 90000 | G9: =IF(A9<>"", F9/ VLOOKUP(A9, 'Курс валют'!$A:$D, 4, 0), "") -> 7.3770492
A10: 46060 | B10: Макарон | C10: кг | D10: 24 | E10: 10000 | F10: =[1]Бозорлик!$D10*[1]Бозорлик!$E10 -> 240000 | G10: =IF(A10<>"", F10/ VLOOKUP(A10, 'Курс валют'!$A:$D, 4, 0), "") -> 19.672131
A11: 46060 | B11: Картошка | C11: кг | D11: 44 | E11: 7500 | F11: =[1]Бозорлик!$D11*[1]Бозорлик!$E11 -> 330000 | G11: =IF(A11<>"", F11/ VLOOKUP(A11, 'Курс валют'!$A:$D, 4, 0), "") -> 27.04918
A12: 46060 | B12: Сабзи | C12: кг | D12: 61 | E12: 5900 | F12: =[1]Бозорлик!$D12*[1]Бозорлик!$E12 -> 359900 | G12: =IF(A12<>"", F12/ VLOOKUP(A12, 'Курс валют'!$A:$D, 4, 0), "") -> 29.5
A13: 46060 | B13: Туз | C13: блок | D13: 1 | E13: 100000 | F13: =[1]Бозорлик!$D13*[1]Бозорлик!$E13 -> 100000 | G13: =IF(A13<>"", F13/ VLOOKUP(A13, 'Курс валют'!$A:$D, 4, 0), "") -> 8.1967213
A14: 46060 | B14: Тухум | C14: решетка | D14: 6 | E14: 45000 | F14: =[1]Бозорлик!$D14*[1]Бозорлик!$E14 -> 270000 | G14: =IF(A14<>"", F14/ VLOOKUP(A14, 'Курс валют'!$A:$D, 4, 0), "") -> 22.131148
A15: 46060 | B15: Сарёг | C15: кг | D15: 2 | E15: 45000 | F15: =[1]Бозорлик!$D15*[1]Бозорлик!$E15 -> 90000 | G15: =IF(A15<>"", F15/ VLOOKUP(A15, 'Курс валют'!$A:$D, 4, 0), "") -> 7.3770492
A16: 46060 | B16: Чеснок | C16: кг | D16: 2 | E16: 30000 | F16: =[1]Бозорлик!$D16*[1]Бозорлик!$E16 -> 60000 | G16: =IF(A16<>"", F16/ VLOOKUP(A16, 'Курс валют'!$A:$D, 4, 0), "") -> 4.9180328
A17: 46060 | B17: Канд | C17: кг | D17: 10 | E17: 15000 | F17: =[1]Бозорлик!$D17*[1]Бозорлик!$E17 -> 150000 | G17: =IF(A17<>"", F17/ VLOOKUP(A17, 'Курс валют'!$A:$D, 4, 0), "") -> 12.295082
A18: 46060 | B18: Филе | C18: кг | D18: 10 | E18: 46000 | F18: =[1]Бозорлик!$D18*[1]Бозорлик!$E18 -> 460000 | G18: =IF(A18<>"", F18/ VLOOKUP(A18, 'Курс валют'!$A:$D, 4, 0), "") -> 37.704918
A19: 07.02.2026 Итог | F19: =SUBTOTAL(9,F8:F18) -> 2349900 | G19: =IF(A19<>"", F19/ VLOOKUP(A19, 'Курс валют'!$A:$D, 4, 0), "") -> #N/A
A20: 46063 | B20: Пахта ёг | C20: литр | D20: 10 | E20: 20000 | F20: =[1]Бозорлик!$D20*[1]Бозорлик!$E20 -> 200000 | G20: =IF(A20<>"", F20/ VLOOKUP(A20, 'Курс валют'!$A:$D, 4, 0), "") -> 16.393443
A21: 46063 | B21: Писта ёг | C21: литр | D21: 10 | E21: 20000 | F21: =[1]Бозорлик!$D21*[1]Бозорлик!$E21 -> 200000 | G21: =IF(A21<>"", F21/ VLOOKUP(A21, 'Курс валют'!$A:$D, 4, 0), "") -> 16.393443
A22: 46063 | B22: Гушт | C22: кг | D22: 20 | E22: 80000 | F22: =[1]Бозорлик!$D22*[1]Бозорлик!$E22 -> 1600000 | G22: =IF(A22<>"", F22/ VLOOKUP(A22, 'Курс валют'!$A:$D, 4, 0), "") -> 131.14754
A23: 46063 | B23: Тухум | C23: решетка | D23: 10 | E23: 45000 | F23: =[1]Бозорлик!$D23*[1]Бозорлик!$E23 -> 450000 | G23: =IF(A23<>"", F23/ VLOOKUP(A23, 'Курс валют'!$A:$D, 4, 0), "") -> 36.885246
A24: 46063 | B24: Сарёг | C24: кг | D24: 5 | E24: 45000 | F24: =[1]Бозорлик!$D24*[1]Бозорлик!$E24 -> 225000 | G24: =IF(A24<>"", F24/ VLOOKUP(A24, 'Курс валют'!$A:$D, 4, 0), "") -> 18.442623
A25: 46063 | B25: Пиёз | C25: кг | D25: 37 | E25: 3500 | F25: =[1]Бозорлик!$D25*[1]Бозорлик!$E25 -> 129500 | G25: =IF(A25<>"", F25/ VLOOKUP(A25, 'Курс валют'!$A:$D, 4, 0), "") -> 10.614754
A26: 46063 | B26: Сабзи | C26: кг | D26: 129 | E26: 6000 | F26: =[1]Бозорлик!$D26*[1]Бозорлик!$E26 -> 774000 | G26: =IF(A26<>"", F26/ VLOOKUP(A26, 'Курс валют'!$A:$D, 4, 0), "") -> 63.442623
A27: 46063 | B27: Туруп | C27: кг | D27: 44 | E27: 6000 | F27: =[1]Бозорлик!$D27*[1]Бозорлик!$E27 -> 264000 | G27: =IF(A27<>"", F27/ VLOOKUP(A27, 'Курс валют'!$A:$D, 4, 0), "") -> 21.639344
A28: 46063 | B28: Пичок | C28: шт | D28: 5 | E28: 10000 | F28: =[1]Бозорлик!$D28*[1]Бозорлик!$E28 -> 50000 | G28: =IF(A28<>"", F28/ VLOOKUP(A28, 'Курс валют'!$A:$D, 4, 0), "") -> 4.0983607
A29: 46063 | B29: Боз | C29: метр | D29: 5 | E29: 14000 | F29: =[1]Бозорлик!$D29*[1]Бозорлик!$E29 -> 70000 | G29: =IF(A29<>"", F29/ VLOOKUP(A29, 'Курс валют'!$A:$D, 4, 0), "") -> 5.7377049
A30: 10.02.2026 Итог | F30: =SUBTOTAL(9,F20:F29) -> 3962500 | G30: =IF(A30<>"", F30/ VLOOKUP(A30, 'Курс валют'!$A:$D, 4, 0), "") -> #N/A
A31: 46067 | B31: Гуруч | C31: кг | D31: 160 | E31: 14000 | F31: =[1]Бозорлик!$D31*[1]Бозорлик!$E31 -> 2240000 | G31: =IF(A31<>"", F31/ VLOOKUP(A31, 'Курс валют'!$A:$D, 4, 0), "") -> 183.90805
A32: 14.02.2026 Итог | F32: =SUBTOTAL(9,F31:F31) -> 2240000 | G32: =IF(A32<>"", F32/ VLOOKUP(A32, 'Курс валют'!$A:$D, 4, 0), "") -> #N/A
A33: 46070 | B33: Гушт | C33: кг | D33: 5 | E33: 90000 | F33: =[1]Бозорлик!$D33*[1]Бозорлик!$E33 -> 450000 | G33: =IF(A33<>"", F33/ VLOOKUP(A33, 'Курс валют'!$A:$D, 4, 0), "") -> 37.037037
A34: 46070 | B34: Кук чой | C34: кг | D34: 2 | E34: 70000 | F34: =[1]Бозорлик!$D34*[1]Бозорлик!$E34 -> 140000 | G34: =IF(A34<>"", F34/ VLOOKUP(A34, 'Курс валют'!$A:$D, 4, 0), "") -> 11.522634
A35: 46070 | B35: Сарёг | C35: кг | D35: 7 | E35: 50000 | F35: =[1]Бозорлик!$D35*[1]Бозорлик!$E35 -> 350000 | G35: =IF(A35<>"", F35/ VLOOKUP(A35, 'Курс валют'!$A:$D, 4, 0), "") -> 28.806584
A36: 46070 | B36: Тухум | C36: решетка | D36: 10 | E36: 45000 | F36: =[1]Бозорлик!$D36*[1]Бозорлик!$E36 -> 450000 | G36: =IF(A36<>"", F36/ VLOOKUP(A36, 'Курс валют'!$A:$D, 4, 0), "") -> 37.037037
A37: 46070 | B37: Гречка | C37: кг | D37: 10 | E37: 14000 | F37: =[1]Бозорлик!$D37*[1]Бозорлик!$E37 -> 140000 | G37: =IF(A37<>"", F37/ VLOOKUP(A37, 'Курс валют'!$A:$D, 4, 0), "") -> 11.522634
A38: 46070 | B38: Доставка | C38: услуга | D38: 1 | E38: 70000 | F38: =[1]Бозорлик!$D38*[1]Бозорлик!$E38 -> 70000 | G38: =IF(A38<>"", F38/ VLOOKUP(A38, 'Курс валют'!$A:$D, 4, 0), "") -> 5.7613169
A39: 17.02.2026 Итог | F39: =SUBTOTAL(9,F33:F38) -> 1600000 | G39: =IF(A39<>"", F39/ VLOOKUP(A39, 'Курс валют'!$A:$D, 4, 0), "") -> #N/A
A40: 46071 | B40: Гушт | C40: кг | D40: 18 | E40: 100000 | F40: =[1]Бозорлик!$D40*[1]Бозорлик!$E40 -> 1800000 | G40: =IF(A40<>"", F40/ VLOOKUP(A40, 'Курс валют'!$A:$D, 4, 0), "") -> 149.00662
...

Sheet Снабжения
A1: КАРТОЧКА СКЛАДСКОГО УЧЕТА ТОВАРА
A2: Дата | B2: Наименование | C2: Ед.Изм | D2: Категория | E2: Приход | F2: Расход | G2: Цена за ед. | H2: Сумма прихода | I2: Сумма расхода | J2: Статус заказа | K2: Способ оплаты | L2: Кому отдано | M2: Ед.из | N2: Остатка | O2: Поставщик/Получатель
A3: 45962 | B3: Арава | C3: шт | D3: Прочее | E3: 4 | F3: 0 | G3: 690000 | H3: =G3*E3 -> 2760000 | I3: =H3*F3 -> 0 | J3: Завершен | K3: Наличные | M3: шт | N3: =SUMIF(B:B,B3,E:E)-SUMIF(B:B,B3,F:F) -> 4 | P3: =IF(A3<>"", Снабжения!H3 / VLOOKUP(A3, 'Курс валют'!$A:$D, 4, 0), "") -> 228.09917
A4: 45962 | B4: Лопата штиковой | C4: шт | D4: Ручной инструменты | E4: 10 | F4: 0 | G4: 17739 | H4: =G4*E4 -> 177390 | I4: =H4*F4 -> 0 | J4: Завершен | K4: Наличные | M4: шт | N4: =SUMIF(B:B,B4,E:E)-SUMIF(B:B,B4,F:F) -> 10 | P4: =IF(A4<>"", Снабжения!H4 / VLOOKUP(A4, 'Курс валют'!$A:$D, 4, 0), "") -> 14.660331
A5: 45962 | B5: Лопата сопковой | C5: шт | D5: Ручной инструменты | E5: 10 | F5: 0 | G5: 17739 | H5: =G5*E5 -> 177390 | I5: =H5*F5 -> 0 | J5: Завершен | K5: Наличные | M5: шт | N5: =SUMIF(B:B,B5,E:E)-SUMIF(B:B,B5,F:F) -> 5 | P5: =IF(A5<>"", Снабжения!H5 / VLOOKUP(A5, 'Курс валют'!$A:$D, 4, 0), "") -> 14.660331
A6: 45962 | B6: Кетмон | C6: шт | D6: Ручной инструменты | E6: 10 | F6: 0 | G6: 32562 | H6: =G6*E6 -> 325620 | I6: =H6*F6 -> 0 | J6: Завершен | K6: Наличные | M6: шт | N6: =SUMIF(B:B,B6,E:E)-SUMIF(B:B,B6,F:F) -> 10 | P6: =IF(A6<>"", Снабжения!H6 / VLOOKUP(A6, 'Курс валют'!$A:$D, 4, 0), "") -> 26.910744
A7: 45962 | B7: Даста лопата | C7: шт | D7: Ручной инструменты | E7: 20 | F7: 7 | G7: 8000 | H7: =G7*E7 -> 160000 | I7: =G7*F7 -> 56000 | J7: Завершен | K7: Наличные | M7: шт | N7: =SUMIF(B:B,B7,E:E)-SUMIF(B:B,B7,F:F) -> 13 | O7: 6 | P7: =IF(A7<>"", Снабжения!H7 / VLOOKUP(A7, 'Курс валют'!$A:$D, 4, 0), "") -> 13.22314
A8: 45962 | B8: Даста кетмон | C8: шт | D8: Ручной инструменты | E8: 10 | F8: 7 | G8: 8000 | H8: =G8*E8 -> 80000 | I8: =G8*F8 -> 56000 | J8: Завершен | K8: Наличные | M8: шт | N8: =SUMIF(B:B,B8,E:E)-SUMIF(B:B,B8,F:F) -> 3 | O8: 0 | P8: =IF(A8<>"", Снабжения!H8 / VLOOKUP(A8, 'Курс валют'!$A:$D, 4, 0), "") -> 6.6115702
A9: 45962 | B9: Леска | C9: шт | E9: 40 | F9: 13 | G9: 3280.5 | H9: =G9*E9 -> 131220 | I9: =G9*F9 -> 42646.5 | J9: Завершен | K9: Наличные | M9: лт | N9: =SUMIF(B:B,B9,E:E)-SUMIF(B:B,B9,F:F) -> 22 | O9: 5 | P9: =IF(A9<>"", Снабжения!H9 / VLOOKUP(A9, 'Курс валют'!$A:$D, 4, 0), "") -> 10.844628
A10: 45962 | B10: Кувалда | C10: шт | D10: Ручной инструменты | E10: 2 | F10: 0 | G10: 95700 | H10: =G10*E10 -> 191400 | I10: =G10*F10 -> 0 | J10: Завершен | K10: Наличные | M10: шт | N10: =SUMIF(B:B,B10,E:E)-SUMIF(B:B,B10,F:F) -> 2 | P10: =IF(A10<>"", Снабжения!H10 / VLOOKUP(A10, 'Курс валют'!$A:$D, 4, 0), "") -> 15.818182
A11: 45962 | B11: Болта | C11: шт | D11: Ручной инструменты | E11: 2 | F11: 0 | H11: =73554+60021 -> 133575 | I11: =G11*F11 -> 0 | J11: Завершен | K11: Наличные | M11: шт | N11: =SUMIF(B:B,B11,E:E)-SUMIF(B:B,B11,F:F) -> 2 | P11: =IF(A11<>"", Снабжения!H11 / VLOOKUP(A11, 'Курс валют'!$A:$D, 4, 0), "") -> 11.039256
A12: 45962 | B12: Болга | C12: шт | D12: Ручной инструменты | E12: 2 | F12: 0 | H12: =29281.5+26851.5 -> 56133 | I12: =G12*F12 -> 0 | J12: Завершен | K12: Наличные | M12: шт | N12: =SUMIF(B:B,B12,E:E)-SUMIF(B:B,B12,F:F) -> 10 | P12: =IF(A12<>"", Снабжения!H12 / VLOOKUP(A12, 'Курс валют'!$A:$D, 4, 0), "") -> 4.6390909
A13: 45962 | B13: Мих 70мм | C13: кг | D13: Мет.из | E13: 20 | G13: 11421 | H13: =G13*E13 -> 228420 | I13: =G13*F13 -> 0 | J13: Завершен | K13: Наличные | M13: шт | N13: =SUMIF(B:B,B13,E:E)-SUMIF(B:B,B13,F:F) -> 40 | O13: 98 | P13: =IF(A13<>"", Снабжения!H13 / VLOOKUP(A13, 'Курс валют'!$A:$D, 4, 0), "") -> 18.877686
A14: 45962 | B14: Мих 100мм | C14: кг | D14: Мет.из | E14: 20 | G14: 11421 | H14: =G14*E14 -> 228420 | I14: =G14*F14 -> 0 | J14: Завершен | K14: Наличные | M14: шт | N14: =SUMIF(B:B,B14,E:E)-SUMIF(B:B,B14,F:F) -> 20 | O14: 80 | P14: =IF(A14<>"", Снабжения!H14 / VLOOKUP(A14, 'Курс валют'!$A:$D, 4, 0), "") -> 18.877686
A15: 45962 | B15: Перчатка | C15: шт | E15: 100 | F15: 30 | G15: 1400 | H15: =G15*E15 -> 140000 | I15: =G15*F15 -> 42000 | J15: Завершен | K15: Наличные | M15: шт | N15: =SUMIF(B:B,B15,E:E)-SUMIF(B:B,B15,F:F) -> 309 | O15: 162 | P15: =IF(A15<>"", Снабжения!H15 / VLOOKUP(A15, 'Курс валют'!$A:$D, 4, 0), "") -> 11.570248
A16: 45962 | B16: Дюбель мих 50 | C16: кг | D16: Мет.из | E16: 20 | G16: 28066.5 | H16: =G16*E16 -> 561330 | I16: =G16*F16 -> 0 | J16: Завершен | K16: Наличные | M16: шт | N16: =SUMIF(B:B,B16,E:E)-SUMIF(B:B,B16,F:F) -> 80 | P16: =IF(A16<>"", Снабжения!H16 / VLOOKUP(A16, 'Курс валют'!$A:$D, 4, 0), "") -> 46.390909
A17: 45962 | B17: Аэрозол Красный | C17: шт | E17: 4 | F17: 4 | G17: 10935 | H17: =G17*E17 -> 43740 | I17: =G17*F17 -> 43740 | J17: Завершен | K17: Наличные | M17: шт | N17: =SUMIF(B:B,B17,E:E)-SUMIF(B:B,B17,F:F) -> 2 | P17: =IF(A17<>"", Снабжения!H17 / VLOOKUP(A17, 'Курс валют'!$A:$D, 4, 0), "") -> 3.614876
A18: 45964 | B18: Болгарка большая О220 | C18: шт | D18: Электроинструменты | E18: 1 | F18: 0 | G18: 748305 | H18: =E18*G18 -> 748305 | I18: =G18*F18 -> 0 | J18: Завершен | K18: Наличные | M18: шт | N18: =SUMIF(B:B,B18,E:E)-SUMIF(B:B,B18,F:F) -> 1 | P18: =IF(A18<>"", Снабжения!H18 / VLOOKUP(A18, 'Курс валют'!$A:$D, 4, 0), "") -> 62.515038
A19: 45964 | B19: Больгарка средняя О180 | C19: шт | D19: Электроинструменты | E19: 1 | F19: 0 | G19: 526585 | H19: =E19*G19 -> 526585 | I19: =G19*F19 -> 0 | J19: Завершен | K19: Наличные | M19: шт | N19: =SUMIF(B:B,B19,E:E)-SUMIF(B:B,B19,F:F) -> 1 | P19: =IF(A19<>"", Снабжения!H19 / VLOOKUP(A19, 'Курс валют'!$A:$D, 4, 0), "") -> 43.992063
A20: 45964 | B20: Пчелка О180 | C20: шт | D20: Электроинструменты | E20: 2 | F20: 0 | G20: 554300 | H20: =E20*G20 -> 1108600 | I20: =G20*F20 -> 0 | J20: Завершен | K20: Наличные | M20: шт | N20: =SUMIF(B:B,B20,E:E)-SUMIF(B:B,B20,F:F) -> 3 | P20: =IF(A20<>"", Снабжения!H20 / VLOOKUP(A20, 'Курс валют'!$A:$D, 4, 0), "") -> 92.614871
A21: 45964 | B21: Вибратор 4м-6м | C21: шт | D21: Электроинструменты | E21: 2 | F21: 0 | G21: =970025+1121132 -> 2091157 | H21: =970025+1121132 -> 2091157 | I21: =G21*F21 -> 0 | J21: Завершен | K21: Наличные | M21: шт | N21: =SUMIF(B:B,B21,E:E)-SUMIF(B:B,B21,F:F) -> 1 | P21: =IF(A21<>"", Снабжения!H21 / VLOOKUP(A21, 'Курс валют'!$A:$D, 4, 0), "") -> 174.69983
A22: 45964 | B22: Уровень длина(80см) | C22: шт | D22: Прочее | E22: 2 | F22: 0 | G22: 60250 | H22: =E22*G22 -> 120500 | I22: =G22*F22 -> 0 | J22: Завершен | K22: Наличные | M22: шт | N22: =SUMIF(B:B,B22,E:E)-SUMIF(B:B,B22,F:F) -> 2 | P22: =IF(A22<>"", Снабжения!H22 / VLOOKUP(A22, 'Курс валют'!$A:$D, 4, 0), "") -> 10.066834
A23: 45964 | B23: Уровень длина(60см) | C23: шт | D23: Прочее | E23: 2 | F23: 0 | G23: 51212.5 | H23: =E23*G23 -> 102425 | I23: =G23*F23 -> 0 | J23: Завершен | K23: Наличные | M23: шт | N23: =SUMIF(B:B,B23,E:E)-SUMIF(B:B,B23,F:F) -> 3 | P23: =IF(A23<>"", Снабжения!H23 / VLOOKUP(A23, 'Курс валют'!$A:$D, 4, 0), "") -> 8.5568087
A24: 45964 | B24: Отвес большой | C24: кг | D24: Прочее | E24: 1 | F24: 0 | G24: 9881 | H24: =E24*G24 -> 9881 | I24: =G24*F24 -> 0 | J24: Завершен | K24: Наличные | M24: шт | N24: =SUMIF(B:B,B24,E:E)-SUMIF(B:B,B24,F:F) -> 1 | P24: =IF(A24<>"", Снабжения!H24 / VLOOKUP(A24, 'Курс валют'!$A:$D, 4, 0), "") -> 0.82548037
A25: 45964 | B25: Шруповерт с аккум | C25: шт | D25: Электроинструменты | E25: 2 | F25: 0 | G25: 1108600 | H25: =E25*G25 -> 2217200 | I25: =G25*F25 -> 0 | J25: Завершен | K25: Наличные | M25: кг | N25: =SUMIF(B:B,B25,E:E)-SUMIF(B:B,B25,F:F) -> 2 | P25: =IF(A25<>"", Снабжения!H25 / VLOOKUP(A25, 'Курс валют'!$A:$D, 4, 0), "") -> 185.22974
A26: 45964 | B26: Перфоратор | C26: шт | D26: Электроинструменты | E26: 2 | F26: 0 | G26: 831450 | H26: =E26*G26 -> 1662900 | I26: =G26*F26 -> 0 | J26: Завершен | K26: Наличные | M26: м | N26: =SUMIF(B:B,B26,E:E)-SUMIF(B:B,B26,F:F) -> 2 | P26: =IF(A26<>"", Снабжения!H26 / VLOOKUP(A26, 'Курс валют'!$A:$D, 4, 0), "") -> 138.92231
A27: 45964 | B27: Тройник | C27: шт | D27: Электрика | E27: 10 | F27: 8 | G27: 10604 | H27: =E27*G27 -> 106040 | I27: =G27*F27 -> 84832 | J27: Завершен | K27: Наличные | M27: м | N27: =SUMIF(B:B,B27,E:E)-SUMIF(B:B,B27,F:F) -> 11 | O27: 12 | P27: =IF(A27<>"", Снабжения!H27 / VLOOKUP(A27, 'Курс валют'!$A:$D, 4, 0), "") -> 8.8588137
A28: 45964 | B28: Вилка | C28: шт | D28: Электрика | E28: 10 | F28: 0 | G28: 3374 | H28: =E28*G28 -> 33740 | I28: =G28*F28 -> 0 | J28: Завершен | K28: Наличные | M28: шт | N28: =SUMIF(B:B,B28,E:E)-SUMIF(B:B,B28,F:F) -> 8 | O28: 6 | P28: =IF(A28<>"", Снабжения!H28 / VLOOKUP(A28, 'Курс валют'!$A:$D, 4, 0), "") -> 2.8187135
A29: 45968 | B29: Этик Резина | C29: шт | D29: Прочее | E29: 20 | F29: 1 | G29: 55000 | H29: =20*55000 -> 1100000 | I29: =G29*F29 -> 55000 | J29: Завершен | K29: Наличные | M29: шт | N29: =SUMIF(B:B,B29,E:E)-SUMIF(B:B,B29,F:F) -> 19 | P29: =IF(A29<>"", Снабжения!H29 / VLOOKUP(A29, 'Курс валют'!$A:$D, 4, 0), "") -> 91.514143
A30: 45968 | B30: Метр 10м | C30: шт | D30: Прочее | E30: 5 | F30: 5 | G30: 31691 | H30: =5*31691 -> 158455 | I30: =G30*F30 -> 158455 | J30: Завершен | K30: Наличные | M30: шт | N30: =SUMIF(B:B,B30,E:E)-SUMIF(B:B,B30,F:F) -> 9 | P30: =IF(A30<>"", Снабжения!H30 / VLOOKUP(A30, 'Курс валют'!$A:$D, 4, 0), "") -> 13.182612
A31: 45968 | B31: Метр 5м | C31: шт | D31: Прочее | E31: 10 | F31: 10 | G31: 15062 | H31: =10*15062 -> 150620 | I31: =G31*F31 -> 150620 | J31: Завершен | K31: Наличные | M31: шт | N31: =SUMIF(B:B,B31,E:E)-SUMIF(B:B,B31,F:F) -> 10 | O31: 0 | P31: =IF(A31<>"", Снабжения!H31 / VLOOKUP(A31, 'Курс валют'!$A:$D, 4, 0), "") -> 12.530782
A32: 45968 | B32: Маркер | C32: шт | D32: Прочее | E32: 20 | F32: 2 | G32: 1205 | H32: =20*1205 -> 24100 | I32: =G32*F32 -> 2410 | J32: Завершен | K32: Наличные | M32: шт | N32: =SUMIF(B:B,B32,E:E)-SUMIF(B:B,B32,F:F) -> 128 | O32: 30 | P32: =IF(A32<>"", Снабжения!H32 / VLOOKUP(A32, 'Курс валют'!$A:$D, 4, 0), "") -> 2.0049917
A33: 45968 | B33: Мель | C33: шт | D33: Прочее | E33: 200 | F33: 2 | I33: =G33*F33 -> 0 | J33: Завершен | K33: Наличные | M33: почка | N33: =SUMIF(B:B,B33,E:E)-SUMIF(B:B,B33,F:F) -> 405 | O33: 525 | P33: =IF(A33<>"", Снабжения!H33 / VLOOKUP(A33, 'Курс валют'!$A:$D, 4, 0), "") -> 0
A34: 45968 | B34: Кабель ПВС 2х2,5 | C34: м | D34: Электрика | E34: 200 | F34: 190 | G34: 12652.64 | H34: =200*12652.64 -> 2530528 | I34: =G34*F34 -> 2404001.6 | J34: Завершен | K34: Наличные | M34: почка | N34: =SUMIF(B:B,B34,E:E)-SUMIF(B:B,B34,F:F) -> 74.5 | P34: =IF(A34<>"", Снабжения!H34 / VLOOKUP(A34, 'Курс валют'!$A:$D, 4, 0), "") -> 210.52646
A35: 45968 | B35: Кабель оддий 3х1,5 | C35: м | D35: Электрика | E35: 40 | F35: 40 | G35: 10163 | H35: =40*10163 -> 406520 | I35: =G35*F35 -> 406520 | J35: Завершен | K35: Наличные | M35: шт | N35: =SUMIF(B:B,B35,E:E)-SUMIF(B:B,B35,F:F) -> 0 | P35: =IF(A35<>"", Снабжения!H35 / VLOOKUP(A35, 'Курс валют'!$A:$D, 4, 0), "") -> 33.8203
A36: 45968 | B36: Акрил лампа 18W | C36: шт | D36: Электрика | E36: 4 | F36: 3 | G36: 14580.5 | H36: =4*14580.5 -> 58322 | I36: =G36*F36 -> 43741.5 | J36: Завершен | K36: Наличные | M36: шт | N36: =SUMIF(B:B,B36,E:E)-SUMIF(B:B,B36,F:F) -> 1 | P36: =IF(A36<>"", Снабжения!H36 / VLOOKUP(A36, 'Курс валют'!$A:$D, 4, 0), "") -> 4.8520799
A37: 45968 | B37: Акрил лампа 24W | C37: шт | D37: Электрика | E37: 1 | F37: 0 | G37: =17232 -> 17232 | H37: =17232 -> 17232 | I37: =G37*F37 -> 0 | J37: Завершен | K37: Наличные | M37: кг | N37: =SUMIF(B:B,B37,E:E)-SUMIF(B:B,B37,F:F) -> 1 | P37: =IF(A37<>"", Снабжения!H37 / VLOOKUP(A37, 'Курс валют'!$A:$D, 4, 0), "") -> 1.4336106
A38: 45968 | B38: Тройник | C38: шт | D38: Электрика | E38: 3 | F38: 3 | G38: 45488 | H38: =3*45488 -> 136464 | I38: =G38*F38 -> 136464 | J38: Завершен | K38: Наличные | M38: кг | N38: =SUMIF(B:B,B38,E:E)-SUMIF(B:B,B38,F:F) -> 11 | P38: =IF(A38<>"", Снабжения!H38 / VLOOKUP(A38, 'Курс валют'!$A:$D, 4, 0), "") -> 11.353078
A39: 45968 | B39: Акрил Лампа (Квадрат) | C39: шт | D39: Электрика | E39: 5 | F39: 5 | G39: 33000 | H39: =33000*5 -> 165000 | I39: =G39*F39 -> 165000 | J39: Завершен | K39: Наличные | M39: кг | N39: =SUMIF(B:B,B39,E:E)-SUMIF(B:B,B39,F:F) -> 0 | P39: =IF(A39<>"", Снабжения!H39 / VLOOKUP(A39, 'Курс валют'!$A:$D, 4, 0), "") -> 13.727121
A40: 45968 | B40: Вилка | C40: шт | D40: Электрика | E40: 3 | F40: 3 | G40: 13616 | H40: =3*13616 -> 40848 | I40: =G40*F40 -> 40848 | J40: Завершен | K40: Наличные | M40: рулон | N40: =SUMIF(B:B,B40,E:E)-SUMIF(B:B,B40,F:F) -> 8 | P40: =IF(A40<>"", Снабжения!H40 / VLOOKUP(A40, 'Курс валют'!$A:$D, 4, 0), "") -> 3.3983361
...

Sheet Арматура приход
A1: № | B1: Дата | C1: Номер Авто | D1: Использовано | E1: Катанка | F1: Использовано10 | G1: D8 | H1: Использовано2 | I1: D10 | J1: Использовано3 | K1: D12 | L1: Использовано4 | M1: D14 | N1: Использовано5 | O1: D16 | P1: Использовано6 | Q1: D18 | R1: Использовано7 | S1: D20 | T1: Использовано8 | U1: D22 | V1: Использовано9 | W1: D25 | X1: Итого | Y1: Угольник (40мм) 4 ст | Z1: Пруд (50) | AA1: Пруд (32) | AB1: Итого2 | AC1: Курс | AD1: В долларе
A2: 1 | B2: 45972 | D2: Да | F2: Да | H2: Да | J2: Да | K2: 3148 | L2: Да | M2: 3063 | N2: Да | P2: Да | Q2: 2873 | R2: Да | S2: 3033 | T2: Да | U2: 3018 | V2: Да | W2: 3053
A3: Приход | B3: 45972 | D3: Да | F3: Да | H3: Да | J3: Да | K3: 3163 | L3: Да | M3: 3058 | N3: Да | P3: Да | R3: Да | S3: 3033 | T3: Да | U3: 3013 | V3: Да | W3: 3048
B4: 45972 | D4: Да | F4: Да | H4: Да | J4: Да | K4: 3153 | L4: Да | M4: 3048 | N4: Да | P4: Да | R4: Да | S4: 3033 | T4: Да | V4: Да
B5: 45972 | D5: Да | F5: Да | H5: Да | J5: Да | K5: 3168 | L5: Да | M5: 3048 | N5: Да | P5: Да | R5: Да | S5: 3053 | T5: Да | V5: Да
B6: 45972 | D6: Да | F6: Да | H6: Да | J6: Да | K6: 3163 | L6: Да | M6: 3063 | N6: Да | P6: Да | R6: Да | T6: Да | V6: Да
B7: 45972 | D7: Да | F7: Да | H7: Да | J7: Да | K7: 3143 | L7: Да | M7: 3058 | N7: Да | P7: Да | R7: Да | T7: Да | V7: Да
B8: 45972 | D8: Да | F8: Да | H8: Да | J8: Да | K8: 3133 | L8: Да | M8: 3053 | N8: Да | P8: Да | R8: Да | T8: Да | V8: Да
B9: 45972 | D9: Да | F9: Да | H9: Да | J9: Да | K9: 3148 | L9: Да | M9: 3053 | N9: Да | P9: Да | R9: Да | T9: Да | V9: Да
B10: 45972 | D10: Да | F10: Да | H10: Да | J10: Да | K10: 3138 | L10: Да | M10: 3053 | N10: Да | P10: Да | R10: Да | T10: Да | V10: Да
B11: 45972 | D11: Да | F11: Да | H11: Да | J11: Да | K11: 3138 | L11: Да | M11: 3053 | N11: Да | P11: Да | R11: Да | T11: Да | V11: Да
B12: 45972 | D12: Да | F12: Да | H12: Да | J12: Да | L12: Да | M12: 3058 | N12: Да | P12: Да | R12: Да | T12: Да | V12: Да
B13: 45972 | D13: Да | F13: Да | H13: Да | J13: Да | L13: Да | M13: 3063 | N13: Да | P13: Да | R13: Да | T13: Да | V13: Да
B14: 45972 | D14: Да | F14: Да | H14: Да | J14: Да | L14: Да | M14: 3048 | N14: Да | P14: Да | R14: Да | T14: Да | V14: Да
B15: 45972 | D15: Да | F15: Да | H15: Да | J15: Да | L15: Да | M15: 3053 | N15: Да | P15: Да | R15: Да | T15: Да | V15: Да | X15: =SUM(K2:K11,M2:M15,Q2,S2:S5,U2:U4,W2:W3) -> 101424 | AB15: =(X15/1000)*640*AC15 -> 7.7471708e+08 | AC15: 11935 | AD15: =(X15/1000)*640 -> 64911.36
A16: 2 | B16: 45985 | D16: Да | F16: Да | H16: Да | J16: Да | L16: Да | N16: Да | P16: Да | R16: Да | T16: Да | V16: Да | Y16: =17*11.7 -> 198.9 | Z16: =11.7*2 -> 23.4 | AA16: =11.7*2 -> 23.4
A17: 3 | B17: 45990 | D17: Да | F17: Да | H17: Да | I17: 3135 | J17: Да | L17: Да | N17: Да | O17: 2600 | P17: Да | Q17: 2410 | R17: Да | T17: Да | U17: 1555 | V17: Да | W17: 2600
A18: Приход | B18: 45990 | D18: Да | F18: Да | H18: Да | I18: 3135 | J18: Да | L18: Да | N18: Да | O18: 5215 | P18: Да | Q18: 2450 | R18: Да | T18: Да | U18: 2485 | V18: Да | W18: 2580
A19: Жамол Ака | B19: 45990 | D19: Да | F19: Да | H19: Да | I19: 3110 | J19: Да | L19: Да | N19: Да | O19: 5200 | P19: Да | Q19: 2515 | R19: Да | T19: Да | U19: 2490 | V19: Да | W19: 2500
B20: 45990 | D20: Да | F20: Да | H20: Да | I20: 3130 | J20: Да | L20: Да | N20: Да | O20: 5135 | P20: Да | Q20: 2500 | R20: Да | T20: Да | U20: 2550 | V20: Да | W20: 2580
B21: 45990 | D21: Да | F21: Да | H21: Да | I21: 3125 | J21: Да | L21: Да | N21: Да | O21: 2555 | P21: Да | Q21: 2540 | R21: Да | T21: Да | U21: 2580 | V21: Да | W21: 2590
B22: 45990 | D22: Да | F22: Да | H22: Да | J22: Да | L22: Да | N22: Да | O22: 2560 | P22: Да | R22: Да | T22: Да | U22: 2580 | V22: Да | W22: 2585
B23: 45990 | D23: Да | F23: Да | H23: Да | J23: Да | L23: Да | N23: Да | O23: 2575 | P23: Да | R23: Да | T23: Да | U23: 2580 | V23: Да | W23: 2510
B24: 45990 | D24: Да | F24: Да | H24: Да | J24: Да | L24: Да | N24: Да | P24: Да | R24: Да | T24: Да | U24: 2585 | V24: Да | W24: 2570
B25: 45990 | D25: Да | F25: Да | H25: Да | J25: Да | L25: Да | N25: Да | P25: Да | R25: Да | T25: Да | U25: 2585 | V25: Да | W25: 2225
B26: 45990 | D26: Да | F26: Да | H26: Да | J26: Да | L26: Да | N26: Да | P26: Да | R26: Да | T26: Да | U26: 2585 | V26: Да | W26: 2165
B27: 45990 | D27: Да | F27: Да | H27: Да | J27: Да | L27: Да | N27: Да | P27: Да | R27: Да | T27: Да | U27: 2585 | V27: Да | W27: 2775
B28: 45990 | D28: Да | F28: Да | H28: Да | J28: Да | L28: Да | N28: Да | P28: Да | R28: Да | T28: Да | U28: 2590 | V28: Да | W28: 2590
B29: 45990 | D29: Да | F29: Да | H29: Да | J29: Да | L29: Да | N29: Да | P29: Да | R29: Да | T29: Да | U29: 2590 | V29: Да
B30: 45990 | D30: Да | F30: Да | H30: Да | J30: Да | L30: Да | N30: Да | P30: Да | R30: Да | T30: Да | U30: 2590 | V30: Да
B31: 45990 | D31: Да | F31: Да | H31: Да | J31: Да | L31: Да | N31: Да | P31: Да | R31: Да | T31: Да | U31: 2600 | V31: Да
B32: 45990 | D32: Да | F32: Да | H32: Да | J32: Да | L32: Да | N32: Да | P32: Да | R32: Да | T32: Да | U32: 2620 | V32: Да
B33: 45990 | D33: Да | F33: Да | H33: Да | J33: Да | L33: Да | N33: Да | P33: Да | R33: Да | T33: Да | U33: 2695 | V33: Да
B34: 45990 | D34: Да | F34: Да | H34: Да | J34: Да | L34: Да | N34: Да | P34: Да | R34: Да | T34: Да | U34: 2930 | V34: Да
B35: 45990 | D35: Да | F35: Да | H35: Да | J35: Да | L35: Да | N35: Да | P35: Да | R35: Да | T35: Да | U35: 3370 | V35: Да
B36: 45990 | D36: Да | F36: Да | H36: Да | J36: Да | L36: Да | N36: Да | P36: Да | R36: Да | T36: Да | U36: 3470 | V36: Да | X36: =SUM(I17:I21,O17:O23,Q17:Q21,U17:U36,W17:W28) -> 136775 | AB36: =(SUM(U32,U34,U36)/1000)*640*AC36 -> 68638592 | AC36: 11890 | AD36: =(SUM(U32,U34,U36)/1000)*640 -> 5772.8
A37: 4 | C37: 788 | D37: Да | F37: Да | H37: Да | J37: Да | L37: Да | N37: Да | O37: 5215 | P37: Да | Q37: 2450 | R37: Да | T37: Да | U37: 1555 | V37: Да | W37: 2590
A38: Возврат | D38: Да | F38: Да | H38: Да | J38: Да | L38: Да | N38: Да | O38: 5135 | P38: Да | Q38: 2410 | R38: Да | T38: Да | U38: 2485 | V38: Да
A39: Жамол Ака | D39: Да | F39: Да | H39: Да | J39: Да | L39: Да | N39: Да | O39: 2555 | P39: Да | R39: Да | T39: Да | U39: 2490 | V39: Да
D40: Да | F40: Да | H40: Да | J40: Да | L40: Да | N40: Да | O40: 2575 | P40: Да | R40: Да | T40: Да | U40: 2550 | V40: Да
...

Sheet Остаток
A1: ОСТАТОК АРМАТУРЫ В РЕАЛЬНОМ ВРЕМЕНИ
A3: Диаметр (D) | B3: Остаток шт/связок | C3: Остаток вес (кг) | D3: Итого использован
A4: Катанка | B4: =SUM('Арматура приход'!$E$2:$E$501,) -> 68805 | C4: =SUMIFS('Арматура приход'!$E$2:$E$501,'Арматура приход'!$D$2:$D$501,"Нет") -> 0 | D4: =B4-C4 -> 68805
A5: 8 | B5: =SUM('Арматура приход'!$G$2:$G$501,) -> 1575 | C5: =SUMIFS('Арматура приход'!$G$2:$G$501,'Арматура приход'!$F$2:$F$501,"Нет") -> 0 | D5: =B5-C5 -> 1575
A6: 10 | B6: =SUM('Арматура приход'!$I$2:$I$501,) -> 82145 | C6: =SUMIFS('Арматура приход'!$I$2:$I$501,'Арматура приход'!$H$2:$H$501,"Нет") -> 0 | D6: =B6-C6 -> 82145
A7: 12 | B7: =SUM('Арматура приход'!$K$2:$K$501,) -> 250200 | C7: =SUMIFS('Арматура приход'!$K$2:$K$501,'Арматура приход'!$J$2:$J$501,"Нет") -> 0 | D7: =B7-C7 -> 250200
A8: 14 | B8: =SUM('Арматура приход'!$M$2:$M$501,) -> 97237 | C8: =SUMIFS('Арматура приход'!$M$2:$M$501,'Арматура приход'!$L$2:$L$501,"Нет") -> 0 | D8: =B8-C8 -> 97237
A9: 16 | B9: =SUM('Арматура приход'!$O$2:$O$501,) -> 59240 | C9: =SUMIFS('Арматура приход'!$O$2:$O$501,'Арматура приход'!$N$2:$N$501,"Нет") -> 0 | D9: =B9-C9 -> 59240
A10: 18 | B10: =SUM('Арматура приход'!$Q$2:$Q$501,) -> 47678 | C10: =SUMIFS('Арматура приход'!$Q$2:$Q$501,'Арматура приход'!$P$2:$P$501,"Нет") -> 0 | D10: =B10-C10 -> 47678
A11: 20 | B11: =SUM('Арматура приход'!$S$2:$S$501,) -> 19667 | C11: =SUMIFS('Арматура приход'!$S$2:$S$501,'Арматура приход'!$R$2:$R$501,"Нет") -> 0 | D11: =B11-C11 -> 19667
A12: 22 | B12: =SUM('Арматура приход'!$U$2:$U$501,) -> 281381 | C12: =SUMIFS('Арматура приход'!$U$2:$U$501,'Арматура приход'!$T$2:$T$501,"Нет") -> 0 | D12: =B12-C12 -> 281381
A13: 25 | B13: =SUM('Арматура приход'!$W$2:$W$501,) -> 259861 | C13: =SUMIFS('Арматура приход'!$W$2:$W$501,'Арматура приход'!$V$2:$V$501,"Нет") -> 0 | D13: =B13-C13 -> 259861
A14: ИТОГО | B14: =SUM(B4:B13) -> 1167789 | C14: =SUM(C4:C13) -> 0 | D14: =SUM(D4:D13) -> 1167789

Sheet Срочный заказ
A1: СРОЧНО ЗАКАЗАТЬ — товары с низким остатком
A2: Порог остатка: | C2: ← измените, и список обновится
A4: № | B4: Наименование | C4: Ед.изм | D4: Категория | E4: Остаток | F4: Последняя цена за ед. | G4: Поставщик | H4: Не заказывать
A5: 1 | B5: сим | C5: кг | D5: Мет.из | E5: =SUMIF(Снабжения!B:B,B5,Снабжения!E:E)-SUMIF(Снабжения!B:B,B5,Снабжения!F:F) -> 125
A6: 2 | B6: розетка | C6: шт | D6: Электрика | E6: =SUMIF(Снабжения!B:B,B6,Снабжения!E:E)-SUMIF(Снабжения!B:B,B6,Снабжения!F:F) -> 1
A7: 3 | B7: Мих 100мм | C7: кг | D7: Мет.из | E7: =SUMIF(Снабжения!B:B,B7,Снабжения!E:E)-SUMIF(Снабжения!B:B,B7,Снабжения!F:F) -> 20 | F7: 9500 | G7: 80
A8: 4 | B8: Метр 10м | C8: шт | D8: Прочее | E8: =SUMIF(Снабжения!B:B,B8,Снабжения!E:E)-SUMIF(Снабжения!B:B,B8,Снабжения!F:F) -> 9 | F8: 31691
A9: 5 | B9: Кабель оддий 3х1,5 | C9: м | D9: Электрика | E9: =SUMIF(Снабжения!B:B,B9,Снабжения!E:E)-SUMIF(Снабжения!B:B,B9,Снабжения!F:F) -> 0 | F9: 10163
A10: 6 | B10: Акрил Лампа (Квадрат) | C10: шт | D10: Электрика | E10: =SUMIF(Снабжения!B:B,B10,Снабжения!E:E)-SUMIF(Снабжения!B:B,B10,Снабжения!F:F) -> 0 | F10: 33000
A11: 7 | B11: Ошхона(Приборы) | E11: =SUMIF(Снабжения!B:B,B11,Снабжения!E:E)-SUMIF(Снабжения!B:B,B11,Снабжения!F:F) -> 0
A12: 8 | B12: Пализол | C12: рулон | D12: Кровля и изоляция | E12: =SUMIF(Снабжения!B:B,B12,Снабжения!E:E)-SUMIF(Снабжения!B:B,B12,Снабжения!F:F) -> 0
A13: 9 | B13: Фализол | C13: рулон | D13: Кровля и изоляция | E13: =SUMIF(Снабжения!B:B,B13,Снабжения!E:E)-SUMIF(Снабжения!B:B,B13,Снабжения!F:F) -> 0
A14: 10 | B14: Праймер | C14: шт | D14: Кровля и изоляция | E14: =SUMIF(Снабжения!B:B,B14,Снабжения!E:E)-SUMIF(Снабжения!B:B,B14,Снабжения!F:F) -> 0
A15: 11 | B15: Бензин | C15: лт | D15: Кровля и изоляция | E15: =SUMIF(Снабжения!B:B,B15,Снабжения!E:E)-SUMIF(Снабжения!B:B,B15,Снабжения!F:F) -> 0
A16: 12 | B16: Кабель ПВС 2х4 | C16: метр | D16: Электрика | E16: =SUMIF(Снабжения!B:B,B16,Снабжения!E:E)-SUMIF(Снабжения!B:B,B16,Снабжения!F:F) -> 0 | F16: 23072
A17: 13 | B17: Автомат 80А | C17: шт | D17: Электрика | E17: =SUMIF(Снабжения!B:B,B17,Снабжения!E:E)-SUMIF(Снабжения!B:B,B17,Снабжения!F:F) -> 0 | F17: 129150
A18: 14 | B18: Супурги Кичкина | C18: шт | D18: Расходники | E18: =SUMIF(Снабжения!B:B,B18,Снабжения!E:E)-SUMIF(Снабжения!B:B,B18,Снабжения!F:F) -> 0 | F18: 32500
A19: 15 | B19: Мастерок | C19: шт | D19: Ручной инструменты | E19: =SUMIF(Снабжения!B:B,B19,Снабжения!E:E)-SUMIF(Снабжения!B:B,B19,Снабжения!F:F) -> 0 | F19: 30000
A20: 16 | B20: Пенопласт | C20: шт | D20: Расходники | E20: =SUMIF(Снабжения!B:B,B20,Снабжения!E:E)-SUMIF(Снабжения!B:B,B20,Снабжения!F:F) -> 0 | F20: 603684
A21: 17 | B21: Колодка | C21: шт | D21: Электрика | E21: =SUMIF(Снабжения!B:B,B21,Снабжения!E:E)-SUMIF(Снабжения!B:B,B21,Снабжения!F:F) -> 0 | F21: 11224
A22: 18 | B22: Кабель сварки | C22: метр | D22: Электрика | E22: =SUMIF(Снабжения!B:B,B22,Снабжения!E:E)-SUMIF(Снабжения!B:B,B22,Снабжения!F:F) -> 0 | F22: 74000
A23: 19 | B23: Инструмент набор | C23: шт | D23: Ручной инструменты | E23: =SUMIF(Снабжения!B:B,B23,Снабжения!E:E)-SUMIF(Снабжения!B:B,B23,Снабжения!F:F) -> 0 | F23: 410000
A24: 20 | B24: Солидол | C24: кг | D24: Расходники | E24: =SUMIF(Снабжения!B:B,B24,Снабжения!E:E)-SUMIF(Снабжения!B:B,B24,Снабжения!F:F) -> 0 | F24: 80000
A25: 21 | B25: Шприц для солидола | C25: шт | D25: Расходники | E25: =SUMIF(Снабжения!B:B,B25,Снабжения!E:E)-SUMIF(Снабжения!B:B,B25,Снабжения!F:F) -> 0 | F25: 300000
A26: 22 | B26: Профил 60/40/4+Доставка | C26: метр | D26: Мет.из | E26: =SUMIF(Снабжения!B:B,B26,Снабжения!E:E)-SUMIF(Снабжения!B:B,B26,Снабжения!F:F) -> 0
A27: 23 | B27: Запчасти труба | C27: шт | E27: =SUMIF(Снабжения!B:B,B27,Снабжения!E:E)-SUMIF(Снабжения!B:B,B27,Снабжения!F:F) -> 0 | F27: 200000
A28: 24 | B28: Щить Метал 60х40 | C28: шт | D28: Электрика | E28: =SUMIF(Снабжения!B:B,B28,Снабжения!E:E)-SUMIF(Снабжения!B:B,B28,Снабжения!F:F) -> 0
A29: 25 | B29: Кабель ПВС 5х6 | C29: метр | D29: Электрика | E29: =SUMIF(Снабжения!B:B,B29,Снабжения!E:E)-SUMIF(Снабжения!B:B,B29,Снабжения!F:F) -> 0
A30: 26 | B30: Папка-Мамка 380 | C30: шт | D30: Электрика | E30: =SUMIF(Снабжения!B:B,B30,Снабжения!E:E)-SUMIF(Снабжения!B:B,B30,Снабжения!F:F) -> 0
A31: 27 | B31: Автомат 250А | C31: шт | D31: Электрика | E31: =SUMIF(Снабжения!B:B,B31,Снабжения!E:E)-SUMIF(Снабжения!B:B,B31,Снабжения!F:F) -> 0
A32: 28 | B32: Автомат 160А | C32: шт | D32: Электрика | E32: =SUMIF(Снабжения!B:B,B32,Снабжения!E:E)-SUMIF(Снабжения!B:B,B32,Снабжения!F:F) -> 0
A33: 29 | B33: Автомат 40А | C33: шт | D33: Электрика | E33: =SUMIF(Снабжения!B:B,B33,Снабжения!E:E)-SUMIF(Снабжения!B:B,B33,Снабжения!F:F) -> 0
A34: 30 | B34: Автомат 25А | C34: шт | D34: Электрика | E34: =SUMIF(Снабжения!B:B,B34,Снабжения!E:E)-SUMIF(Снабжения!B:B,B34,Снабжения!F:F) -> 0
A35: 31 | B35: Ноль клемма | C35: шт | D35: Электрика | E35: =SUMIF(Снабжения!B:B,B35,Снабжения!E:E)-SUMIF(Снабжения!B:B,B35,Снабжения!F:F) -> 0
A36: 32 | B36: Наконечник алюмин | C36: шт | D36: Электрика | E36: =SUMIF(Снабжения!B:B,B36,Снабжения!E:E)-SUMIF(Снабжения!B:B,B36,Снабжения!F:F) -> 0
A37: 33 | B37: Прожектор | C37: шт | D37: Электрика | E37: =SUMIF(Снабжения!B:B,B37,Снабжения!E:E)-SUMIF(Снабжения!B:B,B37,Снабжения!F:F) -> 0
A38: 34 | B38: Динорейка | C38: шт | D38: Электрика | E38: =SUMIF(Снабжения!B:B,B38,Снабжения!E:E)-SUMIF(Снабжения!B:B,B38,Снабжения!F:F) -> 0
A39: 35 | B39: Леска | C39: шт | D39: Расходники | E39: =SUMIF(Снабжения!B:B,B39,Снабжения!E:E)-SUMIF(Снабжения!B:B,B39,Снабжения!F:F) -> 22 | F39: 4900 | G39: 5
A40: 36 | B40: Болгарка большая О220 | C40: шт | D40: Электроинструменты | E40: =SUMIF(Снабжения!B:B,B40,Снабжения!E:E)-SUMIF(Снабжения!B:B,B40,Снабжения!F:F) -> 1 | F40: 748305
A41: 37 | B41: Больгарка средняя О180 | C41: шт | D41: Электроинструменты | E41: =SUMIF(Снабжения!B:B,B41,Снабжения!E:E)-SUMIF(Снабжения!B:B,B41,Снабжения!F:F) -> 1 | F41: 526585
...

Sheet Контакты
A1: 📞 КОНТАКТЫ • GREEN TASHKENT
A3: № | B3: 👤 Имя | C3: 💼 Должность / Что делает | D3: 📱 Телефон | E3: 🏢 Организация | F3: 📝 Примечание
A4: =ROW()-3 -> 1 | B4: Нурсаид | C4: Разнорабочий,Охрана | D4: +998 93 763 22 32 | E4: Мева Шарбат Илмий Экспереминтал
A5: =ROW()-3 -> 2 | B5: Артизан | C5: Сув чикариш хизмати | D5: +998 99 200 80 00 | E5: -
A6: =ROW()-3 -> 3 | B6: Олим Ака | C6: Повар | D6: +998 93 094 26 67 | E6: Мева Шарбат Илмий Экспереминтал
A7: =ROW()-3 -> 4 | B7: Мурод Ака | C7: Бозорлик | D7: +998 88 188 81 14 | E7: Юнусобод Бозор
A8: =ROW()-3 -> 5 | B8: Миродил | C8: Охрана | D8: +998 97 599 94 01 | E8: Мева Шарбат Илмий Экспереминтал
A9: =ROW()-3 -> 6 | B9: Садулла Ака | C9: Бухгалтерия | D9: +998 97 146 69 46 | E9: Мева Шарбат Илмий Экспереминтал
A10: =ROW()-3 -> 7 | B10: Хабибулло | C10: Менеджер | D10: +998 99 895 52 72 | E10: Мева Шарбат Илмий Экспереминтал
A11: =ROW()-3 -> 8 | B11: Миржалол | C11: Разнорабочий,Охрана | D11: +998 93 042 49 39 | E11: Мева Шарбат Илмий Экспереминтал
A12: =ROW()-3 -> 9 | B12: Фазлиддин Ака | C12: Электрик | D12: +998 90 933 90 07 | E12: Мева Шарбат Илмий Экспереминтал
A13: =ROW()-3 -> 10 | B13: Элер | C13: Экскаватор 140В | D13: +998 97 035 27 35 | E13: -
A14: =ROW()-3 -> 11 | B14: Хайрулла | C14: Мой Опалубка | D14: +998 90 973 07 08 | E14: -
A15: =ROW()-3 -> 12 | B15: - | C15: Экскаватор 60В | D15: +998 95 767 97 87 | E15: -
... A23: =ROW()-3 -> 20 | B23: Дилшод Ака | C23: Ремень-Подшибники | D23: +998 98 368 33 31 | E23: -
A24: =ROW()-3 -> 21 | B24: Камера | C24: Камера наблюдение | D24: +998 95 551 90 90
A25: =ROW()-3 -> 22 | D25: +998
A26: =ROW()-3 -> 23 | D26: +998
A27: =ROW()-3 -> 24 | D27: +998
A28: =ROW()-3 -> 25 | D28: +998
A29: =ROW()-3 -> 26 | D29: +998
A30: =ROW()-3 -> 27 | D30: +998
A31: =ROW()-3 -> 28 | D31: +998
A32: =ROW()-3 -> 29 | D32: +998
A33: =ROW()-3 -> 30 | D33: +998
A34: =ROW()-3 -> 31 | D34: +998
A35: =ROW()-3 -> 32 | D35: +998
A36: =ROW()-3 -> 33 | D36: +998
... A53: =ROW()-3 -> 50 | D53: +998

Sheet Бетон
A1: Дата | B1: Грузоотправитель | C1: Номер авто | D1: Марка бетона | E1: Кол-во | F1: Сумма | G1: По доллару
A2: 45978 | B2: ООО "ADAMANT SAVDO PLYUS" | C2: 01 125 QKA | D2: М400 | E2: 9 | F2: =IF(D2="М400", E2*740000, IF(D2="M150", E2*600000, IF(D2="M300", E2*670000, IF(D2="M350", E2*700000, 0)))) -> 6660000 | G2: =IF(A2<>"", F2/ VLOOKUP(A2, '[1]Курс валют'!$A:$D, 4, 0), "") -> 564.40678
A3: 45978 | B3: ООО "ADAMANT SAVDO PLYUS" | C3: 01 М021795 | D3: М400 | E3: 10 | F3: =IF(D3="М400", E3*740000, IF(D3="M150", E3*600000, IF(D3="M300", E3*670000, IF(D3="M350", E3*700000, 0)))) -> 7400000 | G3: =IF(A3<>"", F3/ VLOOKUP(A3, '[1]Курс валют'!$A:$D, 4, 0), "") -> 627.11864
